WARNING:tensorflow:From /home/grupo01/tensorflow/models/research/deeplab/core/conv2d_ws.py:40: The name tf.layers.Layer is deprecated. Please use tf.compat.v1.layers.Layer instead.

WARNING:tensorflow:
The TensorFlow contrib module will not be included in TensorFlow 2.0.
For more information, please see:
  * https://github.com/tensorflow/community/blob/master/rfcs/20180907-contrib-sunset.md
  * https://github.com/tensorflow/addons
  * https://github.com/tensorflow/io (for I/O related ops)
If you depend on functionality not listed there, please file an issue.

WARNING:tensorflow:From train.py:462: The name tf.app.run is deprecated. Please use tf.compat.v1.app.run instead.

WARNING:tensorflow:From train.py:272: The name tf.logging.set_verbosity is deprecated. Please use tf.compat.v1.logging.set_verbosity instead.

W0414 16:40:18.907043 139704792852224 module_wrapper.py:139] From train.py:272: The name tf.logging.set_verbosity is deprecated. Please use tf.compat.v1.logging.set_verbosity instead.

WARNING:tensorflow:From train.py:272: The name tf.logging.INFO is deprecated. Please use tf.compat.v1.logging.INFO instead.

W0414 16:40:18.907215 139704792852224 module_wrapper.py:139] From train.py:272: The name tf.logging.INFO is deprecated. Please use tf.compat.v1.logging.INFO instead.

WARNING:tensorflow:From train.py:287: The name tf.gfile.MakeDirs is deprecated. Please use tf.io.gfile.makedirs instead.

W0414 16:40:18.907434 139704792852224 module_wrapper.py:139] From train.py:287: The name tf.gfile.MakeDirs is deprecated. Please use tf.io.gfile.makedirs instead.

WARNING:tensorflow:From train.py:288: The name tf.logging.info is deprecated. Please use tf.compat.v1.logging.info instead.

W0414 16:40:18.907594 139704792852224 module_wrapper.py:139] From train.py:288: The name tf.logging.info is deprecated. Please use tf.compat.v1.logging.info instead.

INFO:tensorflow:Training on train_fine set
I0414 16:40:18.907681 139704792852224 train.py:288] Training on train_fine set
WARNING:tensorflow:From train.py:312: The name tf.train.get_or_create_global_step is deprecated. Please use tf.compat.v1.train.get_or_create_global_step instead.

W0414 16:40:18.909134 139704792852224 module_wrapper.py:139] From train.py:312: The name tf.train.get_or_create_global_step is deprecated. Please use tf.compat.v1.train.get_or_create_global_step instead.

WARNING:tensorflow:From /home/grupo01/tensorflow/models/research/deeplab/datasets/data_generator.py:350: The name tf.gfile.Glob is deprecated. Please use tf.io.gfile.glob instead.

W0414 16:40:18.916138 139704792852224 module_wrapper.py:139] From /home/grupo01/tensorflow/models/research/deeplab/datasets/data_generator.py:350: The name tf.gfile.Glob is deprecated. Please use tf.io.gfile.glob instead.

WARNING:tensorflow:From /home/grupo01/anaconda3/lib/python3.7/site-packages/tensorflow_core/python/autograph/converters/directives.py:119: The name tf.FixedLenFeature is deprecated. Please use tf.io.FixedLenFeature instead.

W0414 16:40:19.061093 139704792852224 module_wrapper.py:139] From /home/grupo01/anaconda3/lib/python3.7/site-packages/tensorflow_core/python/autograph/converters/directives.py:119: The name tf.FixedLenFeature is deprecated. Please use tf.io.FixedLenFeature instead.

WARNING:tensorflow:From /home/grupo01/anaconda3/lib/python3.7/site-packages/tensorflow_core/python/autograph/converters/directives.py:119: The name tf.parse_single_example is deprecated. Please use tf.io.parse_single_example instead.

W0414 16:40:19.062093 139704792852224 module_wrapper.py:139] From /home/grupo01/anaconda3/lib/python3.7/site-packages/tensorflow_core/python/autograph/converters/directives.py:119: The name tf.parse_single_example is deprecated. Please use tf.io.parse_single_example instead.

2020-04-14 16:40:19.573291: I tensorflow/stream_executor/platform/default/dso_loader.cc:44] Successfully opened dynamic library libcuda.so.1
2020-04-14 16:40:19.658377: I tensorflow/core/common_runtime/gpu/gpu_device.cc:1618] Found device 0 with properties: 
name: TITAN X (Pascal) major: 6 minor: 1 memoryClockRate(GHz): 1.531
pciBusID: 0000:0b:00.0
2020-04-14 16:40:19.658646: I tensorflow/stream_executor/platform/default/dso_loader.cc:44] Successfully opened dynamic library libcudart.so.10.0
2020-04-14 16:40:19.660685: I tensorflow/stream_executor/platform/default/dso_loader.cc:44] Successfully opened dynamic library libcublas.so.10.0
2020-04-14 16:40:19.662270: I tensorflow/stream_executor/platform/default/dso_loader.cc:44] Successfully opened dynamic library libcufft.so.10.0
2020-04-14 16:40:19.662573: I tensorflow/stream_executor/platform/default/dso_loader.cc:44] Successfully opened dynamic library libcurand.so.10.0
2020-04-14 16:40:19.664236: I tensorflow/stream_executor/platform/default/dso_loader.cc:44] Successfully opened dynamic library libcusolver.so.10.0
2020-04-14 16:40:19.665566: I tensorflow/stream_executor/platform/default/dso_loader.cc:44] Successfully opened dynamic library libcusparse.so.10.0
2020-04-14 16:40:19.671572: I tensorflow/stream_executor/platform/default/dso_loader.cc:44] Successfully opened dynamic library libcudnn.so.7
2020-04-14 16:40:19.677998: I tensorflow/core/common_runtime/gpu/gpu_device.cc:1746] Adding visible gpu devices: 0
WARNING:tensorflow:From /home/grupo01/anaconda3/lib/python3.7/site-packages/tensorflow_core/python/autograph/converters/directives.py:119: The name tf.random_uniform is deprecated. Please use tf.random.uniform instead.

W0414 16:40:20.815992 139704792852224 module_wrapper.py:139] From /home/grupo01/anaconda3/lib/python3.7/site-packages/tensorflow_core/python/autograph/converters/directives.py:119: The name tf.random_uniform is deprecated. Please use tf.random.uniform instead.

WARNING:tensorflow:From /home/grupo01/anaconda3/lib/python3.7/site-packages/tensorflow_core/python/autograph/converters/directives.py:119: The name tf.lin_space is deprecated. Please use tf.linspace instead.

W0414 16:40:20.816620 139704792852224 module_wrapper.py:139] From /home/grupo01/anaconda3/lib/python3.7/site-packages/tensorflow_core/python/autograph/converters/directives.py:119: The name tf.lin_space is deprecated. Please use tf.linspace instead.

WARNING:tensorflow:From /home/grupo01/anaconda3/lib/python3.7/site-packages/tensorflow_core/python/autograph/converters/directives.py:119: The name tf.random_shuffle is deprecated. Please use tf.random.shuffle instead.

W0414 16:40:20.816880 139704792852224 module_wrapper.py:139] From /home/grupo01/anaconda3/lib/python3.7/site-packages/tensorflow_core/python/autograph/converters/directives.py:119: The name tf.random_shuffle is deprecated. Please use tf.random.shuffle instead.

WARNING:tensorflow:From /home/grupo01/anaconda3/lib/python3.7/site-packages/tensorflow_core/python/autograph/converters/directives.py:119: The name tf.image.resize_bilinear is deprecated. Please use tf.compat.v1.image.resize_bilinear instead.

W0414 16:40:21.044793 139704792852224 module_wrapper.py:139] From /home/grupo01/anaconda3/lib/python3.7/site-packages/tensorflow_core/python/autograph/converters/directives.py:119: The name tf.image.resize_bilinear is deprecated. Please use tf.compat.v1.image.resize_bilinear instead.

WARNING:tensorflow:From /home/grupo01/anaconda3/lib/python3.7/site-packages/tensorflow_core/python/autograph/converters/directives.py:119: The name tf.reverse_v2 is deprecated. Please use tf.reverse instead.

W0414 16:40:23.358528 139704792852224 module_wrapper.py:139] From /home/grupo01/anaconda3/lib/python3.7/site-packages/tensorflow_core/python/autograph/converters/directives.py:119: The name tf.reverse_v2 is deprecated. Please use tf.reverse instead.

WARNING:tensorflow:From /home/grupo01/tensorflow/models/research/deeplab/datasets/data_generator.py:339: DatasetV1.make_one_shot_iterator (from tensorflow.python.data.ops.dataset_ops) is deprecated and will be removed in a future version.
Instructions for updating:
Use `for ... in dataset:` to iterate over a dataset. If using `tf.estimator`, return the `Dataset` object directly from your input function. As a last resort, you can use `tf.compat.v1.data.make_one_shot_iterator(dataset)`.
W0414 16:40:23.589052 139704792852224 deprecation.py:323] From /home/grupo01/tensorflow/models/research/deeplab/datasets/data_generator.py:339: DatasetV1.make_one_shot_iterator (from tensorflow.python.data.ops.dataset_ops) is deprecated and will be removed in a future version.
Instructions for updating:
Use `for ... in dataset:` to iterate over a dataset. If using `tf.estimator`, return the `Dataset` object directly from your input function. As a last resort, you can use `tf.compat.v1.data.make_one_shot_iterator(dataset)`.
WARNING:tensorflow:From /home/grupo01/tensorflow/models/research/slim/deployment/model_deploy.py:192: The name tf.variable_scope is deprecated. Please use tf.compat.v1.variable_scope instead.

W0414 16:40:23.607393 139704792852224 module_wrapper.py:139] From /home/grupo01/tensorflow/models/research/slim/deployment/model_deploy.py:192: The name tf.variable_scope is deprecated. Please use tf.compat.v1.variable_scope instead.

WARNING:tensorflow:From /home/grupo01/tensorflow/models/research/slim/deployment/model_deploy.py:192: The name tf.get_variable_scope is deprecated. Please use tf.compat.v1.get_variable_scope instead.

W0414 16:40:23.607587 139704792852224 module_wrapper.py:139] From /home/grupo01/tensorflow/models/research/slim/deployment/model_deploy.py:192: The name tf.get_variable_scope is deprecated. Please use tf.compat.v1.get_variable_scope instead.

WARNING:tensorflow:From /home/grupo01/tensorflow/models/research/deeplab/model.py:320: The name tf.AUTO_REUSE is deprecated. Please use tf.compat.v1.AUTO_REUSE instead.

W0414 16:40:23.610046 139704792852224 module_wrapper.py:139] From /home/grupo01/tensorflow/models/research/deeplab/model.py:320: The name tf.AUTO_REUSE is deprecated. Please use tf.compat.v1.AUTO_REUSE instead.

WARNING:tensorflow:From /home/grupo01/tensorflow/models/research/deeplab/core/feature_extractor.py:490: to_float (from tensorflow.python.ops.math_ops) is deprecated and will be removed in a future version.
Instructions for updating:
Use `tf.cast` instead.
W0414 16:40:23.610502 139704792852224 deprecation.py:323] From /home/grupo01/tensorflow/models/research/deeplab/core/feature_extractor.py:490: to_float (from tensorflow.python.ops.math_ops) is deprecated and will be removed in a future version.
Instructions for updating:
Use `tf.cast` instead.
WARNING:tensorflow:From /home/grupo01/anaconda3/lib/python3.7/site-packages/tensorflow_core/contrib/layers/python/layers/layers.py:1057: Layer.apply (from tensorflow.python.keras.engine.base_layer) is deprecated and will be removed in a future version.
Instructions for updating:
Please use `layer.__call__` method instead.
W0414 16:40:23.614977 139704792852224 deprecation.py:323] From /home/grupo01/anaconda3/lib/python3.7/site-packages/tensorflow_core/contrib/layers/python/layers/layers.py:1057: Layer.apply (from tensorflow.python.keras.engine.base_layer) is deprecated and will be removed in a future version.
Instructions for updating:
Please use `layer.__call__` method instead.
WARNING:tensorflow:From /home/grupo01/tensorflow/models/research/deeplab/utils/train_utils.py:158: The name tf.losses.add_loss is deprecated. Please use tf.compat.v1.losses.add_loss instead.

W0414 16:40:28.644633 139704792852224 module_wrapper.py:139] From /home/grupo01/tensorflow/models/research/deeplab/utils/train_utils.py:158: The name tf.losses.add_loss is deprecated. Please use tf.compat.v1.losses.add_loss instead.

WARNING:tensorflow:From train.py:324: The name tf.get_collection is deprecated. Please use tf.compat.v1.get_collection instead.

W0414 16:40:28.645185 139704792852224 module_wrapper.py:139] From train.py:324: The name tf.get_collection is deprecated. Please use tf.compat.v1.get_collection instead.

WARNING:tensorflow:From train.py:324: The name tf.GraphKeys is deprecated. Please use tf.compat.v1.GraphKeys instead.

W0414 16:40:28.645319 139704792852224 module_wrapper.py:139] From train.py:324: The name tf.GraphKeys is deprecated. Please use tf.compat.v1.GraphKeys instead.

WARNING:tensorflow:From train.py:330: The name tf.model_variables is deprecated. Please use tf.compat.v1.model_variables instead.

W0414 16:40:28.645473 139704792852224 module_wrapper.py:139] From train.py:330: The name tf.model_variables is deprecated. Please use tf.compat.v1.model_variables instead.

WARNING:tensorflow:From train.py:331: The name tf.summary.histogram is deprecated. Please use tf.compat.v1.summary.histogram instead.

W0414 16:40:28.645650 139704792852224 module_wrapper.py:139] From train.py:331: The name tf.summary.histogram is deprecated. Please use tf.compat.v1.summary.histogram instead.

WARNING:tensorflow:From train.py:359: The name tf.summary.scalar is deprecated. Please use tf.compat.v1.summary.scalar instead.

W0414 16:40:29.593088 139704792852224 module_wrapper.py:139] From train.py:359: The name tf.summary.scalar is deprecated. Please use tf.compat.v1.summary.scalar instead.

INFO:tensorflow:Setting decay_steps to total training steps.
I0414 16:40:29.596421 139704792852224 train_utils.py:327] Setting decay_steps to total training steps.
WARNING:tensorflow:From /home/grupo01/tensorflow/models/research/deeplab/utils/train_utils.py:337: The name tf.train.polynomial_decay is deprecated. Please use tf.compat.v1.train.polynomial_decay instead.

W0414 16:40:29.596572 139704792852224 module_wrapper.py:139] From /home/grupo01/tensorflow/models/research/deeplab/utils/train_utils.py:337: The name tf.train.polynomial_decay is deprecated. Please use tf.compat.v1.train.polynomial_decay instead.

WARNING:tensorflow:From /home/grupo01/tensorflow/models/research/deeplab/utils/train_utils.py:372: where (from tensorflow.python.ops.array_ops) is deprecated and will be removed in a future version.
Instructions for updating:
Use tf.where in 2.0, which has the same broadcast rule as np.where
W0414 16:40:29.605244 139704792852224 deprecation.py:323] From /home/grupo01/tensorflow/models/research/deeplab/utils/train_utils.py:372: where (from tensorflow.python.ops.array_ops) is deprecated and will be removed in a future version.
Instructions for updating:
Use tf.where in 2.0, which has the same broadcast rule as np.where
WARNING:tensorflow:From train.py:378: The name tf.train.MomentumOptimizer is deprecated. Please use tf.compat.v1.train.MomentumOptimizer instead.

W0414 16:40:29.607480 139704792852224 module_wrapper.py:139] From train.py:378: The name tf.train.MomentumOptimizer is deprecated. Please use tf.compat.v1.train.MomentumOptimizer instead.

WARNING:tensorflow:From train.py:396: The name tf.check_numerics is deprecated. Please use tf.debugging.check_numerics instead.

W0414 16:40:32.245566 139704792852224 module_wrapper.py:139] From train.py:396: The name tf.check_numerics is deprecated. Please use tf.debugging.check_numerics instead.

WARNING:tensorflow:From train.py:422: The name tf.summary.merge is deprecated. Please use tf.compat.v1.summary.merge instead.

W0414 16:40:34.940691 139704792852224 module_wrapper.py:139] From train.py:422: The name tf.summary.merge is deprecated. Please use tf.compat.v1.summary.merge instead.

WARNING:tensorflow:From train.py:425: The name tf.ConfigProto is deprecated. Please use tf.compat.v1.ConfigProto instead.

W0414 16:40:34.959786 139704792852224 module_wrapper.py:139] From train.py:425: The name tf.ConfigProto is deprecated. Please use tf.compat.v1.ConfigProto instead.

INFO:tensorflow:Ignoring initialization; other checkpoint exists
I0414 16:40:34.963741 139704792852224 train_utils.py:204] Ignoring initialization; other checkpoint exists
WARNING:tensorflow:From /home/grupo01/anaconda3/lib/python3.7/site-packages/tensorflow_core/contrib/slim/python/slim/learning.py:742: Supervisor.__init__ (from tensorflow.python.training.supervisor) is deprecated and will be removed in a future version.
Instructions for updating:
Please switch to tf.train.MonitoredTrainingSession
W0414 16:40:37.001767 139704792852224 deprecation.py:323] From /home/grupo01/anaconda3/lib/python3.7/site-packages/tensorflow_core/contrib/slim/python/slim/learning.py:742: Supervisor.__init__ (from tensorflow.python.training.supervisor) is deprecated and will be removed in a future version.
Instructions for updating:
Please switch to tf.train.MonitoredTrainingSession
2020-04-14 16:40:38.143135: I tensorflow/core/platform/cpu_feature_guard.cc:142] Your CPU supports instructions that this TensorFlow binary was not compiled to use: AVX2 FMA
2020-04-14 16:40:38.162592: I tensorflow/core/platform/profile_utils/cpu_utils.cc:94] CPU Frequency: 2099865000 Hz
2020-04-14 16:40:38.163457: I tensorflow/compiler/xla/service/service.cc:168] XLA service 0x55caf600de20 initialized for platform Host (this does not guarantee that XLA will be used). Devices:
2020-04-14 16:40:38.163479: I tensorflow/compiler/xla/service/service.cc:176]   StreamExecutor device (0): Host, Default Version
2020-04-14 16:40:38.384569: I tensorflow/compiler/xla/service/service.cc:168] XLA service 0x55caf5ef9dd0 initialized for platform CUDA (this does not guarantee that XLA will be used). Devices:
2020-04-14 16:40:38.384610: I tensorflow/compiler/xla/service/service.cc:176]   StreamExecutor device (0): TITAN X (Pascal), Compute Capability 6.1
2020-04-14 16:40:38.387628: I tensorflow/core/common_runtime/gpu/gpu_device.cc:1618] Found device 0 with properties: 
name: TITAN X (Pascal) major: 6 minor: 1 memoryClockRate(GHz): 1.531
pciBusID: 0000:0b:00.0
2020-04-14 16:40:38.387725: I tensorflow/stream_executor/platform/default/dso_loader.cc:44] Successfully opened dynamic library libcudart.so.10.0
2020-04-14 16:40:38.387752: I tensorflow/stream_executor/platform/default/dso_loader.cc:44] Successfully opened dynamic library libcublas.so.10.0
2020-04-14 16:40:38.387785: I tensorflow/stream_executor/platform/default/dso_loader.cc:44] Successfully opened dynamic library libcufft.so.10.0
2020-04-14 16:40:38.387813: I tensorflow/stream_executor/platform/default/dso_loader.cc:44] Successfully opened dynamic library libcurand.so.10.0
2020-04-14 16:40:38.387834: I tensorflow/stream_executor/platform/default/dso_loader.cc:44] Successfully opened dynamic library libcusolver.so.10.0
2020-04-14 16:40:38.387857: I tensorflow/stream_executor/platform/default/dso_loader.cc:44] Successfully opened dynamic library libcusparse.so.10.0
2020-04-14 16:40:38.387880: I tensorflow/stream_executor/platform/default/dso_loader.cc:44] Successfully opened dynamic library libcudnn.so.7
2020-04-14 16:40:38.397402: I tensorflow/core/common_runtime/gpu/gpu_device.cc:1746] Adding visible gpu devices: 0
2020-04-14 16:40:38.397631: I tensorflow/stream_executor/platform/default/dso_loader.cc:44] Successfully opened dynamic library libcudart.so.10.0
2020-04-14 16:40:38.401853: I tensorflow/core/common_runtime/gpu/gpu_device.cc:1159] Device interconnect StreamExecutor with strength 1 edge matrix:
2020-04-14 16:40:38.401875: I tensorflow/core/common_runtime/gpu/gpu_device.cc:1165]      0 
2020-04-14 16:40:38.401881: I tensorflow/core/common_runtime/gpu/gpu_device.cc:1178] 0:   N 
2020-04-14 16:40:38.408583: I tensorflow/core/common_runtime/gpu/gpu_device.cc:1304] Created TensorFlow device (/job:localhost/replica:0/task:0/device:GPU:0 with 11448 MB memory) -> physical GPU (device: 0, name: TITAN X (Pascal), pci bus id: 0000:0b:00.0, compute capability: 6.1)
INFO:tensorflow:Restoring parameters from ./datasets/cityscapes/exp/train_on_train_set/train/exp2/model.ckpt-13932
I0414 16:40:38.411469 139704792852224 saver.py:1284] Restoring parameters from ./datasets/cityscapes/exp/train_on_train_set/train/exp2/model.ckpt-13932
2020-04-14 16:40:40.976536: W tensorflow/core/framework/op_kernel.cc:1651] OP_REQUIRES failed at save_restore_v2_ops.cc:184 : Not found: Key xception_71/entry_flow/block1/unit_1/xception_module/separable_conv1_depthwise/BatchNorm/beta not found in checkpoint
INFO:tensorflow:Error reported to Coordinator: <class 'tensorflow.python.framework.errors_impl.NotFoundError'>, Restoring from checkpoint failed. This is most likely due to a Variable name or other graph key that is missing from the checkpoint. Please ensure that you have not altered the graph expected based on the checkpoint. Original error:

Key xception_71/entry_flow/block1/unit_1/xception_module/separable_conv1_depthwise/BatchNorm/beta not found in checkpoint
	 [[node save/RestoreV2 (defined at /home/grupo01/anaconda3/lib/python3.7/site-packages/tensorflow_core/python/framework/ops.py:1748) ]]

Original stack trace for 'save/RestoreV2':
  File "train.py", line 462, in <module>
    tf.app.run()
  File "/home/grupo01/anaconda3/lib/python3.7/site-packages/tensorflow_core/python/platform/app.py", line 40, in run
    _run(main=main, argv=argv, flags_parser=_parse_flags_tolerate_undef)
  File "/home/grupo01/anaconda3/lib/python3.7/site-packages/absl/app.py", line 299, in run
    _run_main(main, args)
  File "/home/grupo01/anaconda3/lib/python3.7/site-packages/absl/app.py", line 250, in _run_main
    sys.exit(main(argv))
  File "train.py", line 456, in main
    save_interval_secs=FLAGS.save_interval_secs)
  File "/home/grupo01/anaconda3/lib/python3.7/site-packages/tensorflow_core/contrib/slim/python/slim/learning.py", line 663, in train
    saver = saver or tf_saver.Saver()
  File "/home/grupo01/anaconda3/lib/python3.7/site-packages/tensorflow_core/python/training/saver.py", line 828, in __init__
    self.build()
  File "/home/grupo01/anaconda3/lib/python3.7/site-packages/tensorflow_core/python/training/saver.py", line 840, in build
    self._build(self._filename, build_save=True, build_restore=True)
  File "/home/grupo01/anaconda3/lib/python3.7/site-packages/tensorflow_core/python/training/saver.py", line 878, in _build
    build_restore=build_restore)
  File "/home/grupo01/anaconda3/lib/python3.7/site-packages/tensorflow_core/python/training/saver.py", line 508, in _build_internal
    restore_sequentially, reshape)
  File "/home/grupo01/anaconda3/lib/python3.7/site-packages/tensorflow_core/python/training/saver.py", line 328, in _AddRestoreOps
    restore_sequentially)
  File "/home/grupo01/anaconda3/lib/python3.7/site-packages/tensorflow_core/python/training/saver.py", line 575, in bulk_restore
    return io_ops.restore_v2(filename_tensor, names, slices, dtypes)
  File "/home/grupo01/anaconda3/lib/python3.7/site-packages/tensorflow_core/python/ops/gen_io_ops.py", line 1696, in restore_v2
    name=name)
  File "/home/grupo01/anaconda3/lib/python3.7/site-packages/tensorflow_core/python/framework/op_def_library.py", line 794, in _apply_op_helper
    op_def=op_def)
  File "/home/grupo01/anaconda3/lib/python3.7/site-packages/tensorflow_core/python/util/deprecation.py", line 507, in new_func
    return func(*args, **kwargs)
  File "/home/grupo01/anaconda3/lib/python3.7/site-packages/tensorflow_core/python/framework/ops.py", line 3357, in create_op
    attrs, op_def, compute_device)
  File "/home/grupo01/anaconda3/lib/python3.7/site-packages/tensorflow_core/python/framework/ops.py", line 3426, in _create_op_internal
    op_def=op_def)
  File "/home/grupo01/anaconda3/lib/python3.7/site-packages/tensorflow_core/python/framework/ops.py", line 1748, in __init__
    self._traceback = tf_stack.extract_stack()

I0414 16:40:40.993350 139704792852224 coordinator.py:224] Error reported to Coordinator: <class 'tensorflow.python.framework.errors_impl.NotFoundError'>, Restoring from checkpoint failed. This is most likely due to a Variable name or other graph key that is missing from the checkpoint. Please ensure that you have not altered the graph expected based on the checkpoint. Original error:

Key xception_71/entry_flow/block1/unit_1/xception_module/separable_conv1_depthwise/BatchNorm/beta not found in checkpoint
	 [[node save/RestoreV2 (defined at /home/grupo01/anaconda3/lib/python3.7/site-packages/tensorflow_core/python/framework/ops.py:1748) ]]

Original stack trace for 'save/RestoreV2':
  File "train.py", line 462, in <module>
    tf.app.run()
  File "/home/grupo01/anaconda3/lib/python3.7/site-packages/tensorflow_core/python/platform/app.py", line 40, in run
    _run(main=main, argv=argv, flags_parser=_parse_flags_tolerate_undef)
  File "/home/grupo01/anaconda3/lib/python3.7/site-packages/absl/app.py", line 299, in run
    _run_main(main, args)
  File "/home/grupo01/anaconda3/lib/python3.7/site-packages/absl/app.py", line 250, in _run_main
    sys.exit(main(argv))
  File "train.py", line 456, in main
    save_interval_secs=FLAGS.save_interval_secs)
  File "/home/grupo01/anaconda3/lib/python3.7/site-packages/tensorflow_core/contrib/slim/python/slim/learning.py", line 663, in train
    saver = saver or tf_saver.Saver()
  File "/home/grupo01/anaconda3/lib/python3.7/site-packages/tensorflow_core/python/training/saver.py", line 828, in __init__
    self.build()
  File "/home/grupo01/anaconda3/lib/python3.7/site-packages/tensorflow_core/python/training/saver.py", line 840, in build
    self._build(self._filename, build_save=True, build_restore=True)
  File "/home/grupo01/anaconda3/lib/python3.7/site-packages/tensorflow_core/python/training/saver.py", line 878, in _build
    build_restore=build_restore)
  File "/home/grupo01/anaconda3/lib/python3.7/site-packages/tensorflow_core/python/training/saver.py", line 508, in _build_internal
    restore_sequentially, reshape)
  File "/home/grupo01/anaconda3/lib/python3.7/site-packages/tensorflow_core/python/training/saver.py", line 328, in _AddRestoreOps
    restore_sequentially)
  File "/home/grupo01/anaconda3/lib/python3.7/site-packages/tensorflow_core/python/training/saver.py", line 575, in bulk_restore
    return io_ops.restore_v2(filename_tensor, names, slices, dtypes)
  File "/home/grupo01/anaconda3/lib/python3.7/site-packages/tensorflow_core/python/ops/gen_io_ops.py", line 1696, in restore_v2
    name=name)
  File "/home/grupo01/anaconda3/lib/python3.7/site-packages/tensorflow_core/python/framework/op_def_library.py", line 794, in _apply_op_helper
    op_def=op_def)
  File "/home/grupo01/anaconda3/lib/python3.7/site-packages/tensorflow_core/python/util/deprecation.py", line 507, in new_func
    return func(*args, **kwargs)
  File "/home/grupo01/anaconda3/lib/python3.7/site-packages/tensorflow_core/python/framework/ops.py", line 3357, in create_op
    attrs, op_def, compute_device)
  File "/home/grupo01/anaconda3/lib/python3.7/site-packages/tensorflow_core/python/framework/ops.py", line 3426, in _create_op_internal
    op_def=op_def)
  File "/home/grupo01/anaconda3/lib/python3.7/site-packages/tensorflow_core/python/framework/ops.py", line 1748, in __init__
    self._traceback = tf_stack.extract_stack()

Traceback (most recent call last):
  File "/home/grupo01/anaconda3/lib/python3.7/site-packages/tensorflow_core/python/client/session.py", line 1365, in _do_call
    return fn(*args)
  File "/home/grupo01/anaconda3/lib/python3.7/site-packages/tensorflow_core/python/client/session.py", line 1350, in _run_fn
    target_list, run_metadata)
  File "/home/grupo01/anaconda3/lib/python3.7/site-packages/tensorflow_core/python/client/session.py", line 1443, in _call_tf_sessionrun
    run_metadata)
tensorflow.python.framework.errors_impl.NotFoundError: Key xception_71/entry_flow/block1/unit_1/xception_module/separable_conv1_depthwise/BatchNorm/beta not found in checkpoint
	 [[{{node save/RestoreV2}}]]

During handling of the above exception, another exception occurred:

Traceback (most recent call last):
  File "/home/grupo01/anaconda3/lib/python3.7/site-packages/tensorflow_core/python/training/saver.py", line 1290, in restore
    {self.saver_def.filename_tensor_name: save_path})
  File "/home/grupo01/anaconda3/lib/python3.7/site-packages/tensorflow_core/python/client/session.py", line 956, in run
    run_metadata_ptr)
  File "/home/grupo01/anaconda3/lib/python3.7/site-packages/tensorflow_core/python/client/session.py", line 1180, in _run
    feed_dict_tensor, options, run_metadata)
  File "/home/grupo01/anaconda3/lib/python3.7/site-packages/tensorflow_core/python/client/session.py", line 1359, in _do_run
    run_metadata)
  File "/home/grupo01/anaconda3/lib/python3.7/site-packages/tensorflow_core/python/client/session.py", line 1384, in _do_call
    raise type(e)(node_def, op, message)
tensorflow.python.framework.errors_impl.NotFoundError: Key xception_71/entry_flow/block1/unit_1/xception_module/separable_conv1_depthwise/BatchNorm/beta not found in checkpoint
	 [[node save/RestoreV2 (defined at /home/grupo01/anaconda3/lib/python3.7/site-packages/tensorflow_core/python/framework/ops.py:1748) ]]

Original stack trace for 'save/RestoreV2':
  File "train.py", line 462, in <module>
    tf.app.run()
  File "/home/grupo01/anaconda3/lib/python3.7/site-packages/tensorflow_core/python/platform/app.py", line 40, in run
    _run(main=main, argv=argv, flags_parser=_parse_flags_tolerate_undef)
  File "/home/grupo01/anaconda3/lib/python3.7/site-packages/absl/app.py", line 299, in run
    _run_main(main, args)
  File "/home/grupo01/anaconda3/lib/python3.7/site-packages/absl/app.py", line 250, in _run_main
    sys.exit(main(argv))
  File "train.py", line 456, in main
    save_interval_secs=FLAGS.save_interval_secs)
  File "/home/grupo01/anaconda3/lib/python3.7/site-packages/tensorflow_core/contrib/slim/python/slim/learning.py", line 663, in train
    saver = saver or tf_saver.Saver()
  File "/home/grupo01/anaconda3/lib/python3.7/site-packages/tensorflow_core/python/training/saver.py", line 828, in __init__
    self.build()
  File "/home/grupo01/anaconda3/lib/python3.7/site-packages/tensorflow_core/python/training/saver.py", line 840, in build
    self._build(self._filename, build_save=True, build_restore=True)
  File "/home/grupo01/anaconda3/lib/python3.7/site-packages/tensorflow_core/python/training/saver.py", line 878, in _build
    build_restore=build_restore)
  File "/home/grupo01/anaconda3/lib/python3.7/site-packages/tensorflow_core/python/training/saver.py", line 508, in _build_internal
    restore_sequentially, reshape)
  File "/home/grupo01/anaconda3/lib/python3.7/site-packages/tensorflow_core/python/training/saver.py", line 328, in _AddRestoreOps
    restore_sequentially)
  File "/home/grupo01/anaconda3/lib/python3.7/site-packages/tensorflow_core/python/training/saver.py", line 575, in bulk_restore
    return io_ops.restore_v2(filename_tensor, names, slices, dtypes)
  File "/home/grupo01/anaconda3/lib/python3.7/site-packages/tensorflow_core/python/ops/gen_io_ops.py", line 1696, in restore_v2
    name=name)
  File "/home/grupo01/anaconda3/lib/python3.7/site-packages/tensorflow_core/python/framework/op_def_library.py", line 794, in _apply_op_helper
    op_def=op_def)
  File "/home/grupo01/anaconda3/lib/python3.7/site-packages/tensorflow_core/python/util/deprecation.py", line 507, in new_func
    return func(*args, **kwargs)
  File "/home/grupo01/anaconda3/lib/python3.7/site-packages/tensorflow_core/python/framework/ops.py", line 3357, in create_op
    attrs, op_def, compute_device)
  File "/home/grupo01/anaconda3/lib/python3.7/site-packages/tensorflow_core/python/framework/ops.py", line 3426, in _create_op_internal
    op_def=op_def)
  File "/home/grupo01/anaconda3/lib/python3.7/site-packages/tensorflow_core/python/framework/ops.py", line 1748, in __init__
    self._traceback = tf_stack.extract_stack()


During handling of the above exception, another exception occurred:

Traceback (most recent call last):
  File "/home/grupo01/anaconda3/lib/python3.7/site-packages/tensorflow_core/python/training/saver.py", line 1300, in restore
    names_to_keys = object_graph_key_mapping(save_path)
  File "/home/grupo01/anaconda3/lib/python3.7/site-packages/tensorflow_core/python/training/saver.py", line 1618, in object_graph_key_mapping
    object_graph_string = reader.get_tensor(trackable.OBJECT_GRAPH_PROTO_KEY)
  File "/home/grupo01/anaconda3/lib/python3.7/site-packages/tensorflow_core/python/pywrap_tensorflow_internal.py", line 915, in get_tensor
    return CheckpointReader_GetTensor(self, compat.as_bytes(tensor_str))
tensorflow.python.framework.errors_impl.NotFoundError: Key _CHECKPOINTABLE_OBJECT_GRAPH not found in checkpoint

During handling of the above exception, another exception occurred:

Traceback (most recent call last):
  File "train.py", line 462, in <module>
    tf.app.run()
  File "/home/grupo01/anaconda3/lib/python3.7/site-packages/tensorflow_core/python/platform/app.py", line 40, in run
    _run(main=main, argv=argv, flags_parser=_parse_flags_tolerate_undef)
  File "/home/grupo01/anaconda3/lib/python3.7/site-packages/absl/app.py", line 299, in run
    _run_main(main, args)
  File "/home/grupo01/anaconda3/lib/python3.7/site-packages/absl/app.py", line 250, in _run_main
    sys.exit(main(argv))
  File "train.py", line 456, in main
    save_interval_secs=FLAGS.save_interval_secs)
  File "/home/grupo01/anaconda3/lib/python3.7/site-packages/tensorflow_core/contrib/slim/python/slim/learning.py", line 753, in train
    master, start_standard_services=False, config=session_config) as sess:
  File "/home/grupo01/anaconda3/lib/python3.7/contextlib.py", line 112, in __enter__
    return next(self.gen)
  File "/home/grupo01/anaconda3/lib/python3.7/site-packages/tensorflow_core/python/training/supervisor.py", line 1014, in managed_session
    self.stop(close_summary_writer=close_summary_writer)
  File "/home/grupo01/anaconda3/lib/python3.7/site-packages/tensorflow_core/python/training/supervisor.py", line 839, in stop
    ignore_live_threads=ignore_live_threads)
  File "/home/grupo01/anaconda3/lib/python3.7/site-packages/tensorflow_core/python/training/coordinator.py", line 389, in join
    six.reraise(*self._exc_info_to_raise)
  File "/home/grupo01/anaconda3/lib/python3.7/site-packages/six.py", line 693, in reraise
    raise value
  File "/home/grupo01/anaconda3/lib/python3.7/site-packages/tensorflow_core/python/training/supervisor.py", line 1003, in managed_session
    start_standard_services=start_standard_services)
  File "/home/grupo01/anaconda3/lib/python3.7/site-packages/tensorflow_core/python/training/supervisor.py", line 734, in prepare_or_wait_for_session
    init_fn=self._init_fn)
  File "/home/grupo01/anaconda3/lib/python3.7/site-packages/tensorflow_core/python/training/session_manager.py", line 290, in prepare_session
    config=config)
  File "/home/grupo01/anaconda3/lib/python3.7/site-packages/tensorflow_core/python/training/session_manager.py", line 220, in _restore_checkpoint
    saver.restore(sess, ckpt.model_checkpoint_path)
  File "/home/grupo01/anaconda3/lib/python3.7/site-packages/tensorflow_core/python/training/saver.py", line 1306, in restore
    err, "a Variable name or other graph key that is missing")
tensorflow.python.framework.errors_impl.NotFoundError: Restoring from checkpoint failed. This is most likely due to a Variable name or other graph key that is missing from the checkpoint. Please ensure that you have not altered the graph expected based on the checkpoint. Original error:

Key xception_71/entry_flow/block1/unit_1/xception_module/separable_conv1_depthwise/BatchNorm/beta not found in checkpoint
	 [[node save/RestoreV2 (defined at /home/grupo01/anaconda3/lib/python3.7/site-packages/tensorflow_core/python/framework/ops.py:1748) ]]

Original stack trace for 'save/RestoreV2':
  File "train.py", line 462, in <module>
    tf.app.run()
  File "/home/grupo01/anaconda3/lib/python3.7/site-packages/tensorflow_core/python/platform/app.py", line 40, in run
    _run(main=main, argv=argv, flags_parser=_parse_flags_tolerate_undef)
  File "/home/grupo01/anaconda3/lib/python3.7/site-packages/absl/app.py", line 299, in run
    _run_main(main, args)
  File "/home/grupo01/anaconda3/lib/python3.7/site-packages/absl/app.py", line 250, in _run_main
    sys.exit(main(argv))
  File "train.py", line 456, in main
    save_interval_secs=FLAGS.save_interval_secs)
  File "/home/grupo01/anaconda3/lib/python3.7/site-packages/tensorflow_core/contrib/slim/python/slim/learning.py", line 663, in train
    saver = saver or tf_saver.Saver()
  File "/home/grupo01/anaconda3/lib/python3.7/site-packages/tensorflow_core/python/training/saver.py", line 828, in __init__
    self.build()
  File "/home/grupo01/anaconda3/lib/python3.7/site-packages/tensorflow_core/python/training/saver.py", line 840, in build
    self._build(self._filename, build_save=True, build_restore=True)
  File "/home/grupo01/anaconda3/lib/python3.7/site-packages/tensorflow_core/python/training/saver.py", line 878, in _build
    build_restore=build_restore)
  File "/home/grupo01/anaconda3/lib/python3.7/site-packages/tensorflow_core/python/training/saver.py", line 508, in _build_internal
    restore_sequentially, reshape)
  File "/home/grupo01/anaconda3/lib/python3.7/site-packages/tensorflow_core/python/training/saver.py", line 328, in _AddRestoreOps
    restore_sequentially)
  File "/home/grupo01/anaconda3/lib/python3.7/site-packages/tensorflow_core/python/training/saver.py", line 575, in bulk_restore
    return io_ops.restore_v2(filename_tensor, names, slices, dtypes)
  File "/home/grupo01/anaconda3/lib/python3.7/site-packages/tensorflow_core/python/ops/gen_io_ops.py", line 1696, in restore_v2
    name=name)
  File "/home/grupo01/anaconda3/lib/python3.7/site-packages/tensorflow_core/python/framework/op_def_library.py", line 794, in _apply_op_helper
    op_def=op_def)
  File "/home/grupo01/anaconda3/lib/python3.7/site-packages/tensorflow_core/python/util/deprecation.py", line 507, in new_func
    return func(*args, **kwargs)
  File "/home/grupo01/anaconda3/lib/python3.7/site-packages/tensorflow_core/python/framework/ops.py", line 3357, in create_op
    attrs, op_def, compute_device)
  File "/home/grupo01/anaconda3/lib/python3.7/site-packages/tensorflow_core/python/framework/ops.py", line 3426, in _create_op_internal
    op_def=op_def)
  File "/home/grupo01/anaconda3/lib/python3.7/site-packages/tensorflow_core/python/framework/ops.py", line 1748, in __init__
    self._traceback = tf_stack.extract_stack()

ERROR:tensorflow:==================================
Object was never used (type <class 'tensorflow.python.framework.ops.Tensor'>):
<tf.Tensor 'init_ops/report_uninitialized_variables/boolean_mask/GatherV2:0' shape=(?,) dtype=string>
If you want to mark it as used call its "mark_used()" method.
It was originally created here:
  File "/home/grupo01/anaconda3/lib/python3.7/site-packages/absl/app.py", line 321, in run
    raise  File "/home/grupo01/anaconda3/lib/python3.7/site-packages/absl/app.py", line 250, in _run_main
    sys.exit(main(argv))  File "train.py", line 456, in main
    save_interval_secs=FLAGS.save_interval_secs)  File "/home/grupo01/anaconda3/lib/python3.7/site-packages/tensorflow_core/contrib/slim/python/slim/learning.py", line 796, in train
    should_retry = True  File "/home/grupo01/anaconda3/lib/python3.7/site-packages/tensorflow_core/python/util/tf_should_use.py", line 198, in wrapped
    return _add_should_use_warning(fn(*args, **kwargs))
==================================
E0414 16:40:41.619893 139704792852224 tf_should_use.py:76] ==================================
Object was never used (type <class 'tensorflow.python.framework.ops.Tensor'>):
<tf.Tensor 'init_ops/report_uninitialized_variables/boolean_mask/GatherV2:0' shape=(?,) dtype=string>
If you want to mark it as used call its "mark_used()" method.
It was originally created here:
  File "/home/grupo01/anaconda3/lib/python3.7/site-packages/absl/app.py", line 321, in run
    raise  File "/home/grupo01/anaconda3/lib/python3.7/site-packages/absl/app.py", line 250, in _run_main
    sys.exit(main(argv))  File "train.py", line 456, in main
    save_interval_secs=FLAGS.save_interval_secs)  File "/home/grupo01/anaconda3/lib/python3.7/site-packages/tensorflow_core/contrib/slim/python/slim/learning.py", line 796, in train
    should_retry = True  File "/home/grupo01/anaconda3/lib/python3.7/site-packages/tensorflow_core/python/util/tf_should_use.py", line 198, in wrapped
    return _add_should_use_warning(fn(*args, **kwargs))
==================================
