WARNING:tensorflow:From /home/grupo01/tensorflow/models/research/deeplab/core/conv2d_ws.py:40: The name tf.layers.Layer is deprecated. Please use tf.compat.v1.layers.Layer instead.

WARNING:tensorflow:From eval.py:227: The name tf.app.run is deprecated. Please use tf.compat.v1.app.run instead.

WARNING:tensorflow:From eval.py:91: The name tf.logging.set_verbosity is deprecated. Please use tf.compat.v1.logging.set_verbosity instead.

W0418 11:53:16.844773 140593528387328 module_wrapper.py:139] From eval.py:91: The name tf.logging.set_verbosity is deprecated. Please use tf.compat.v1.logging.set_verbosity instead.

WARNING:tensorflow:From eval.py:91: The name tf.logging.INFO is deprecated. Please use tf.compat.v1.logging.INFO instead.

W0418 11:53:16.844936 140593528387328 module_wrapper.py:139] From eval.py:91: The name tf.logging.INFO is deprecated. Please use tf.compat.v1.logging.INFO instead.

WARNING:tensorflow:From eval.py:108: The name tf.gfile.MakeDirs is deprecated. Please use tf.io.gfile.makedirs instead.

W0418 11:53:16.845129 140593528387328 module_wrapper.py:139] From eval.py:108: The name tf.gfile.MakeDirs is deprecated. Please use tf.io.gfile.makedirs instead.

WARNING:tensorflow:From eval.py:109: The name tf.logging.info is deprecated. Please use tf.compat.v1.logging.info instead.

W0418 11:53:16.845340 140593528387328 module_wrapper.py:139] From eval.py:109: The name tf.logging.info is deprecated. Please use tf.compat.v1.logging.info instead.

INFO:tensorflow:Evaluating on val_fine set
I0418 11:53:16.845424 140593528387328 eval.py:109] Evaluating on val_fine set
WARNING:tensorflow:From /home/grupo01/tensorflow/models/research/deeplab/datasets/data_generator.py:350: The name tf.gfile.Glob is deprecated. Please use tf.io.gfile.glob instead.

W0418 11:53:16.846277 140593528387328 module_wrapper.py:139] From /home/grupo01/tensorflow/models/research/deeplab/datasets/data_generator.py:350: The name tf.gfile.Glob is deprecated. Please use tf.io.gfile.glob instead.

WARNING:tensorflow:From /home/grupo01/anaconda3/lib/python3.7/site-packages/tensorflow_core/python/autograph/converters/directives.py:119: The name tf.FixedLenFeature is deprecated. Please use tf.io.FixedLenFeature instead.

W0418 11:53:17.044308 140593528387328 module_wrapper.py:139] From /home/grupo01/anaconda3/lib/python3.7/site-packages/tensorflow_core/python/autograph/converters/directives.py:119: The name tf.FixedLenFeature is deprecated. Please use tf.io.FixedLenFeature instead.

WARNING:tensorflow:From /home/grupo01/anaconda3/lib/python3.7/site-packages/tensorflow_core/python/autograph/converters/directives.py:119: The name tf.parse_single_example is deprecated. Please use tf.io.parse_single_example instead.

W0418 11:53:17.045487 140593528387328 module_wrapper.py:139] From /home/grupo01/anaconda3/lib/python3.7/site-packages/tensorflow_core/python/autograph/converters/directives.py:119: The name tf.parse_single_example is deprecated. Please use tf.io.parse_single_example instead.

2020-04-18 11:53:17.596817: I tensorflow/stream_executor/platform/default/dso_loader.cc:44] Successfully opened dynamic library libcuda.so.1
2020-04-18 11:53:17.664585: I tensorflow/core/common_runtime/gpu/gpu_device.cc:1618] Found device 0 with properties: 
name: TITAN X (Pascal) major: 6 minor: 1 memoryClockRate(GHz): 1.531
pciBusID: 0000:04:00.0
2020-04-18 11:53:17.664816: I tensorflow/stream_executor/platform/default/dso_loader.cc:44] Successfully opened dynamic library libcudart.so.10.0
2020-04-18 11:53:17.666176: I tensorflow/stream_executor/platform/default/dso_loader.cc:44] Successfully opened dynamic library libcublas.so.10.0
2020-04-18 11:53:17.667405: I tensorflow/stream_executor/platform/default/dso_loader.cc:44] Successfully opened dynamic library libcufft.so.10.0
2020-04-18 11:53:17.667671: I tensorflow/stream_executor/platform/default/dso_loader.cc:44] Successfully opened dynamic library libcurand.so.10.0
2020-04-18 11:53:17.669202: I tensorflow/stream_executor/platform/default/dso_loader.cc:44] Successfully opened dynamic library libcusolver.so.10.0
2020-04-18 11:53:17.670450: I tensorflow/stream_executor/platform/default/dso_loader.cc:44] Successfully opened dynamic library libcusparse.so.10.0
2020-04-18 11:53:17.674372: I tensorflow/stream_executor/platform/default/dso_loader.cc:44] Successfully opened dynamic library libcudnn.so.7
2020-04-18 11:53:17.681807: I tensorflow/core/common_runtime/gpu/gpu_device.cc:1746] Adding visible gpu devices: 0
WARNING:tensorflow:From /home/grupo01/tensorflow/models/research/deeplab/datasets/data_generator.py:339: DatasetV1.make_one_shot_iterator (from tensorflow.python.data.ops.dataset_ops) is deprecated and will be removed in a future version.
Instructions for updating:
Use `for ... in dataset:` to iterate over a dataset. If using `tf.estimator`, return the `Dataset` object directly from your input function. As a last resort, you can use `tf.compat.v1.data.make_one_shot_iterator(dataset)`.
W0418 11:53:19.535046 140593528387328 deprecation.py:323] From /home/grupo01/tensorflow/models/research/deeplab/datasets/data_generator.py:339: DatasetV1.make_one_shot_iterator (from tensorflow.python.data.ops.dataset_ops) is deprecated and will be removed in a future version.
Instructions for updating:
Use `for ... in dataset:` to iterate over a dataset. If using `tf.estimator`, return the `Dataset` object directly from your input function. As a last resort, you can use `tf.compat.v1.data.make_one_shot_iterator(dataset)`.
INFO:tensorflow:Performing single-scale test.
I0418 11:53:19.552241 140593528387328 eval.py:127] Performing single-scale test.
WARNING:tensorflow:From /home/grupo01/tensorflow/models/research/deeplab/model.py:320: The name tf.AUTO_REUSE is deprecated. Please use tf.compat.v1.AUTO_REUSE instead.

W0418 11:53:19.552449 140593528387328 module_wrapper.py:139] From /home/grupo01/tensorflow/models/research/deeplab/model.py:320: The name tf.AUTO_REUSE is deprecated. Please use tf.compat.v1.AUTO_REUSE instead.

WARNING:tensorflow:From /home/grupo01/tensorflow/models/research/deeplab/core/feature_extractor.py:490: to_float (from tensorflow.python.ops.math_ops) is deprecated and will be removed in a future version.
Instructions for updating:
Use `tf.cast` instead.
W0418 11:53:19.552806 140593528387328 deprecation.py:323] From /home/grupo01/tensorflow/models/research/deeplab/core/feature_extractor.py:490: to_float (from tensorflow.python.ops.math_ops) is deprecated and will be removed in a future version.
Instructions for updating:
Use `tf.cast` instead.
WARNING:tensorflow:From /home/grupo01/tensorflow/models/research/deeplab/core/xception.py:469: The name tf.variable_scope is deprecated. Please use tf.compat.v1.variable_scope instead.

W0418 11:53:19.554839 140593528387328 module_wrapper.py:139] From /home/grupo01/tensorflow/models/research/deeplab/core/xception.py:469: The name tf.variable_scope is deprecated. Please use tf.compat.v1.variable_scope instead.

WARNING:tensorflow:From /home/grupo01/anaconda3/lib/python3.7/site-packages/tensorflow_core/contrib/layers/python/layers/layers.py:1057: Layer.apply (from tensorflow.python.keras.engine.base_layer) is deprecated and will be removed in a future version.
Instructions for updating:
Please use `layer.__call__` method instead.
W0418 11:53:19.557011 140593528387328 deprecation.py:323] From /home/grupo01/anaconda3/lib/python3.7/site-packages/tensorflow_core/contrib/layers/python/layers/layers.py:1057: Layer.apply (from tensorflow.python.keras.engine.base_layer) is deprecated and will be removed in a future version.
Instructions for updating:
Please use `layer.__call__` method instead.
WARNING:tensorflow:From /home/grupo01/tensorflow/models/research/deeplab/core/utils.py:41: The name tf.image.resize_bilinear is deprecated. Please use tf.compat.v1.image.resize_bilinear instead.

W0418 11:53:24.038048 140593528387328 module_wrapper.py:139] From /home/grupo01/tensorflow/models/research/deeplab/core/utils.py:41: The name tf.image.resize_bilinear is deprecated. Please use tf.compat.v1.image.resize_bilinear instead.

WARNING:tensorflow:From eval.py:150: where (from tensorflow.python.ops.array_ops) is deprecated and will be removed in a future version.
Instructions for updating:
Use tf.where in 2.0, which has the same broadcast rule as np.where
W0418 11:53:24.311253 140593528387328 deprecation.py:323] From eval.py:150: where (from tensorflow.python.ops.array_ops) is deprecated and will be removed in a future version.
Instructions for updating:
Use tf.where in 2.0, which has the same broadcast rule as np.where
WARNING:tensorflow:From eval.py:161: The name tf.metrics.mean_iou is deprecated. Please use tf.compat.v1.metrics.mean_iou instead.

W0418 11:53:24.312046 140593528387328 module_wrapper.py:139] From eval.py:161: The name tf.metrics.mean_iou is deprecated. Please use tf.compat.v1.metrics.mean_iou instead.

WARNING:tensorflow:From /home/grupo01/anaconda3/lib/python3.7/site-packages/tensorflow_core/python/ops/metrics_impl.py:1178: div (from tensorflow.python.ops.math_ops) is deprecated and will be removed in a future version.
Instructions for updating:
Deprecated in favor of operator or tf.math.divide.
W0418 11:53:24.381460 140593528387328 deprecation.py:323] From /home/grupo01/anaconda3/lib/python3.7/site-packages/tensorflow_core/python/ops/metrics_impl.py:1178: div (from tensorflow.python.ops.math_ops) is deprecated and will be removed in a future version.
Instructions for updating:
Deprecated in favor of operator or tf.math.divide.
WARNING:tensorflow:From eval.py:171: The name tf.metrics.true_positives is deprecated. Please use tf.compat.v1.metrics.true_positives instead.

W0418 11:53:24.391221 140593528387328 module_wrapper.py:139] From eval.py:171: The name tf.metrics.true_positives is deprecated. Please use tf.compat.v1.metrics.true_positives instead.

WARNING:tensorflow:From eval.py:174: The name tf.metrics.false_positives is deprecated. Please use tf.compat.v1.metrics.false_positives instead.

W0418 11:53:24.408457 140593528387328 module_wrapper.py:139] From eval.py:174: The name tf.metrics.false_positives is deprecated. Please use tf.compat.v1.metrics.false_positives instead.

WARNING:tensorflow:From eval.py:177: The name tf.metrics.false_negatives is deprecated. Please use tf.compat.v1.metrics.false_negatives instead.

W0418 11:53:24.425056 140593528387328 module_wrapper.py:139] From eval.py:177: The name tf.metrics.false_negatives is deprecated. Please use tf.compat.v1.metrics.false_negatives instead.

WARNING:tensorflow:From eval.py:191: The name tf.summary.scalar is deprecated. Please use tf.compat.v1.summary.scalar instead.

W0418 11:53:25.420658 140593528387328 module_wrapper.py:139] From eval.py:191: The name tf.summary.scalar is deprecated. Please use tf.compat.v1.summary.scalar instead.

WARNING:tensorflow:From eval.py:192: Print (from tensorflow.python.ops.logging_ops) is deprecated and will be removed after 2018-08-20.
Instructions for updating:
Use tf.print instead of tf.Print. Note that tf.print returns a no-output operator that directly prints the output. Outside of defuns or eager mode, this operator will not be executed unless it is directly specified in session.run or used as a control dependency for other operators. This is only a concern in graph mode. Below is an example of how to ensure tf.print executes in graph mode:

W0418 11:53:25.421798 140593528387328 deprecation.py:323] From eval.py:192: Print (from tensorflow.python.ops.logging_ops) is deprecated and will be removed after 2018-08-20.
Instructions for updating:
Use tf.print instead of tf.Print. Note that tf.print returns a no-output operator that directly prints the output. Outside of defuns or eager mode, this operator will not be executed unless it is directly specified in session.run or used as a control dependency for other operators. This is only a concern in graph mode. Below is an example of how to ensure tf.print executes in graph mode:

WARNING:tensorflow:From eval.py:195: The name tf.summary.merge is deprecated. Please use tf.compat.v1.summary.merge instead.

W0418 11:53:25.453338 140593528387328 module_wrapper.py:139] From eval.py:195: The name tf.summary.merge is deprecated. Please use tf.compat.v1.summary.merge instead.

WARNING:tensorflow:From eval.py:208: The name tf.get_default_graph is deprecated. Please use tf.compat.v1.get_default_graph instead.

W0418 11:53:25.454408 140593528387328 module_wrapper.py:139] From eval.py:208: The name tf.get_default_graph is deprecated. Please use tf.compat.v1.get_default_graph instead.

WARNING:tensorflow:From eval.py:209: print_model_analysis (from tensorflow.contrib.tfprof.model_analyzer) is deprecated and will be removed after 2018-01-01.
Instructions for updating:
Use `tf.profiler.profile(graph, run_meta, op_log, cmd, options)`. Build `options` with `tf.profiler.ProfileOptionBuilder`. See README.md for details
W0418 11:53:25.454526 140593528387328 deprecation.py:323] From eval.py:209: print_model_analysis (from tensorflow.contrib.tfprof.model_analyzer) is deprecated and will be removed after 2018-01-01.
Instructions for updating:
Use `tf.profiler.profile(graph, run_meta, op_log, cmd, options)`. Build `options` with `tf.profiler.ProfileOptionBuilder`. See README.md for details
WARNING:tensorflow:From /home/grupo01/anaconda3/lib/python3.7/site-packages/tensorflow_core/python/profiler/internal/flops_registry.py:142: tensor_shape_from_node_def_name (from tensorflow.python.framework.graph_util_impl) is deprecated and will be removed in a future version.
Instructions for updating:
Use `tf.compat.v1.graph_util.tensor_shape_from_node_def_name`
W0418 11:53:25.455773 140593528387328 deprecation.py:323] From /home/grupo01/anaconda3/lib/python3.7/site-packages/tensorflow_core/python/profiler/internal/flops_registry.py:142: tensor_shape_from_node_def_name (from tensorflow.python.framework.graph_util_impl) is deprecated and will be removed in a future version.
Instructions for updating:
Use `tf.compat.v1.graph_util.tensor_shape_from_node_def_name`
61 ops no flops stats due to incomplete shapes.
61 ops no flops stats due to incomplete shapes.
INFO:tensorflow:Waiting for new checkpoint at ./datasets/cityscapes/exp/train_on_train_set/train/exp4
I0418 11:53:27.257696 140593528387328 evaluation.py:189] Waiting for new checkpoint at ./datasets/cityscapes/exp/train_on_train_set/train/exp4
INFO:tensorflow:Found new checkpoint at ./datasets/cityscapes/exp/train_on_train_set/train/exp4/model.ckpt-30000
I0418 11:53:27.260743 140593528387328 evaluation.py:198] Found new checkpoint at ./datasets/cityscapes/exp/train_on_train_set/train/exp4/model.ckpt-30000
INFO:tensorflow:Graph was finalized.
I0418 11:53:29.203306 140593528387328 monitored_session.py:240] Graph was finalized.
2020-04-18 11:53:29.204230: I tensorflow/core/platform/cpu_feature_guard.cc:142] Your CPU supports instructions that this TensorFlow binary was not compiled to use: AVX2 FMA
2020-04-18 11:53:29.219590: I tensorflow/core/platform/profile_utils/cpu_utils.cc:94] CPU Frequency: 2099885000 Hz
2020-04-18 11:53:29.220918: I tensorflow/compiler/xla/service/service.cc:168] XLA service 0x5640b14d8530 initialized for platform Host (this does not guarantee that XLA will be used). Devices:
2020-04-18 11:53:29.220964: I tensorflow/compiler/xla/service/service.cc:176]   StreamExecutor device (0): Host, Default Version
2020-04-18 11:53:29.451751: I tensorflow/compiler/xla/service/service.cc:168] XLA service 0x5640b05bf210 initialized for platform CUDA (this does not guarantee that XLA will be used). Devices:
2020-04-18 11:53:29.451827: I tensorflow/compiler/xla/service/service.cc:176]   StreamExecutor device (0): TITAN X (Pascal), Compute Capability 6.1
2020-04-18 11:53:29.457180: I tensorflow/core/common_runtime/gpu/gpu_device.cc:1618] Found device 0 with properties: 
name: TITAN X (Pascal) major: 6 minor: 1 memoryClockRate(GHz): 1.531
pciBusID: 0000:04:00.0
2020-04-18 11:53:29.457323: I tensorflow/stream_executor/platform/default/dso_loader.cc:44] Successfully opened dynamic library libcudart.so.10.0
2020-04-18 11:53:29.457374: I tensorflow/stream_executor/platform/default/dso_loader.cc:44] Successfully opened dynamic library libcublas.so.10.0
2020-04-18 11:53:29.457428: I tensorflow/stream_executor/platform/default/dso_loader.cc:44] Successfully opened dynamic library libcufft.so.10.0
2020-04-18 11:53:29.457498: I tensorflow/stream_executor/platform/default/dso_loader.cc:44] Successfully opened dynamic library libcurand.so.10.0
2020-04-18 11:53:29.457561: I tensorflow/stream_executor/platform/default/dso_loader.cc:44] Successfully opened dynamic library libcusolver.so.10.0
2020-04-18 11:53:29.457608: I tensorflow/stream_executor/platform/default/dso_loader.cc:44] Successfully opened dynamic library libcusparse.so.10.0
2020-04-18 11:53:29.457653: I tensorflow/stream_executor/platform/default/dso_loader.cc:44] Successfully opened dynamic library libcudnn.so.7
2020-04-18 11:53:29.470148: I tensorflow/core/common_runtime/gpu/gpu_device.cc:1746] Adding visible gpu devices: 0
2020-04-18 11:53:29.471148: I tensorflow/stream_executor/platform/default/dso_loader.cc:44] Successfully opened dynamic library libcudart.so.10.0
2020-04-18 11:53:29.478060: I tensorflow/core/common_runtime/gpu/gpu_device.cc:1159] Device interconnect StreamExecutor with strength 1 edge matrix:
2020-04-18 11:53:29.478096: I tensorflow/core/common_runtime/gpu/gpu_device.cc:1165]      0 
2020-04-18 11:53:29.478111: I tensorflow/core/common_runtime/gpu/gpu_device.cc:1178] 0:   N 
2020-04-18 11:53:29.491743: I tensorflow/core/common_runtime/gpu/gpu_device.cc:1304] Created TensorFlow device (/job:localhost/replica:0/task:0/device:GPU:0 with 11448 MB memory) -> physical GPU (device: 0, name: TITAN X (Pascal), pci bus id: 0000:04:00.0, compute capability: 6.1)
INFO:tensorflow:Restoring parameters from ./datasets/cityscapes/exp/train_on_train_set/train/exp4/model.ckpt-30000
I0418 11:53:29.495221 140593528387328 saver.py:1284] Restoring parameters from ./datasets/cityscapes/exp/train_on_train_set/train/exp4/model.ckpt-30000
Traceback (most recent call last):
  File "/home/grupo01/anaconda3/lib/python3.7/site-packages/tensorflow_core/python/client/session.py", line 1365, in _do_call
    return fn(*args)
  File "/home/grupo01/anaconda3/lib/python3.7/site-packages/tensorflow_core/python/client/session.py", line 1350, in _run_fn
    target_list, run_metadata)
  File "/home/grupo01/anaconda3/lib/python3.7/site-packages/tensorflow_core/python/client/session.py", line 1443, in _call_tf_sessionrun
    run_metadata)
tensorflow.python.framework.errors_impl.InvalidArgumentError: 2 root error(s) found.
  (0) Invalid argument: Assign requires shapes of both tensors to match. lhs shape= [1,1,1024,256] rhs shape= [1,1,1280,256]
	 [[{{node save/Assign_39}}]]
  (1) Invalid argument: Assign requires shapes of both tensors to match. lhs shape= [1,1,1024,256] rhs shape= [1,1,1280,256]
	 [[{{node save/Assign_39}}]]
	 [[save/RestoreV2/_388]]
0 successful operations.
0 derived errors ignored.

During handling of the above exception, another exception occurred:

Traceback (most recent call last):
  File "/home/grupo01/anaconda3/lib/python3.7/site-packages/tensorflow_core/python/training/saver.py", line 1290, in restore
    {self.saver_def.filename_tensor_name: save_path})
  File "/home/grupo01/anaconda3/lib/python3.7/site-packages/tensorflow_core/python/client/session.py", line 956, in run
    run_metadata_ptr)
  File "/home/grupo01/anaconda3/lib/python3.7/site-packages/tensorflow_core/python/client/session.py", line 1180, in _run
    feed_dict_tensor, options, run_metadata)
  File "/home/grupo01/anaconda3/lib/python3.7/site-packages/tensorflow_core/python/client/session.py", line 1359, in _do_run
    run_metadata)
  File "/home/grupo01/anaconda3/lib/python3.7/site-packages/tensorflow_core/python/client/session.py", line 1384, in _do_call
    raise type(e)(node_def, op, message)
tensorflow.python.framework.errors_impl.InvalidArgumentError: 2 root error(s) found.
  (0) Invalid argument: Assign requires shapes of both tensors to match. lhs shape= [1,1,1024,256] rhs shape= [1,1,1280,256]
	 [[node save/Assign_39 (defined at /home/grupo01/anaconda3/lib/python3.7/site-packages/tensorflow_core/python/framework/ops.py:1748) ]]
  (1) Invalid argument: Assign requires shapes of both tensors to match. lhs shape= [1,1,1024,256] rhs shape= [1,1,1280,256]
	 [[node save/Assign_39 (defined at /home/grupo01/anaconda3/lib/python3.7/site-packages/tensorflow_core/python/framework/ops.py:1748) ]]
	 [[save/RestoreV2/_388]]
0 successful operations.
0 derived errors ignored.

Original stack trace for 'save/Assign_39':
  File "eval.py", line 227, in <module>
    tf.app.run()
  File "/home/grupo01/anaconda3/lib/python3.7/site-packages/tensorflow_core/python/platform/app.py", line 40, in run
    _run(main=main, argv=argv, flags_parser=_parse_flags_tolerate_undef)
  File "/home/grupo01/anaconda3/lib/python3.7/site-packages/absl/app.py", line 299, in run
    _run_main(main, args)
  File "/home/grupo01/anaconda3/lib/python3.7/site-packages/absl/app.py", line 250, in _run_main
    sys.exit(main(argv))
  File "eval.py", line 220, in main
    eval_interval_secs=FLAGS.eval_interval_secs)
  File "/home/grupo01/anaconda3/lib/python3.7/site-packages/tensorflow_core/contrib/training/python/training/evaluation.py", line 448, in evaluate_repeatedly
    session_creator=session_creator, hooks=hooks) as session:
  File "/home/grupo01/anaconda3/lib/python3.7/site-packages/tensorflow_core/python/training/monitored_session.py", line 1014, in __init__
    stop_grace_period_secs=stop_grace_period_secs)
  File "/home/grupo01/anaconda3/lib/python3.7/site-packages/tensorflow_core/python/training/monitored_session.py", line 725, in __init__
    self._sess = _RecoverableSession(self._coordinated_creator)
  File "/home/grupo01/anaconda3/lib/python3.7/site-packages/tensorflow_core/python/training/monitored_session.py", line 1207, in __init__
    _WrappedSession.__init__(self, self._create_session())
  File "/home/grupo01/anaconda3/lib/python3.7/site-packages/tensorflow_core/python/training/monitored_session.py", line 1212, in _create_session
    return self._sess_creator.create_session()
  File "/home/grupo01/anaconda3/lib/python3.7/site-packages/tensorflow_core/python/training/monitored_session.py", line 878, in create_session
    self.tf_sess = self._session_creator.create_session()
  File "/home/grupo01/anaconda3/lib/python3.7/site-packages/tensorflow_core/python/training/monitored_session.py", line 638, in create_session
    self._scaffold.finalize()
  File "/home/grupo01/anaconda3/lib/python3.7/site-packages/tensorflow_core/python/training/monitored_session.py", line 229, in finalize
    self._saver = training_saver._get_saver_or_default()  # pylint: disable=protected-access
  File "/home/grupo01/anaconda3/lib/python3.7/site-packages/tensorflow_core/python/training/saver.py", line 599, in _get_saver_or_default
    saver = Saver(sharded=True, allow_empty=True)
  File "/home/grupo01/anaconda3/lib/python3.7/site-packages/tensorflow_core/python/training/saver.py", line 828, in __init__
    self.build()
  File "/home/grupo01/anaconda3/lib/python3.7/site-packages/tensorflow_core/python/training/saver.py", line 840, in build
    self._build(self._filename, build_save=True, build_restore=True)
  File "/home/grupo01/anaconda3/lib/python3.7/site-packages/tensorflow_core/python/training/saver.py", line 878, in _build
    build_restore=build_restore)
  File "/home/grupo01/anaconda3/lib/python3.7/site-packages/tensorflow_core/python/training/saver.py", line 502, in _build_internal
    restore_sequentially, reshape)
  File "/home/grupo01/anaconda3/lib/python3.7/site-packages/tensorflow_core/python/training/saver.py", line 381, in _AddShardedRestoreOps
    name="restore_shard"))
  File "/home/grupo01/anaconda3/lib/python3.7/site-packages/tensorflow_core/python/training/saver.py", line 350, in _AddRestoreOps
    assign_ops.append(saveable.restore(saveable_tensors, shapes))
  File "/home/grupo01/anaconda3/lib/python3.7/site-packages/tensorflow_core/python/training/saving/saveable_object_util.py", line 73, in restore
    self.op.get_shape().is_fully_defined())
  File "/home/grupo01/anaconda3/lib/python3.7/site-packages/tensorflow_core/python/ops/state_ops.py", line 227, in assign
    validate_shape=validate_shape)
  File "/home/grupo01/anaconda3/lib/python3.7/site-packages/tensorflow_core/python/ops/gen_state_ops.py", line 66, in assign
    use_locking=use_locking, name=name)
  File "/home/grupo01/anaconda3/lib/python3.7/site-packages/tensorflow_core/python/framework/op_def_library.py", line 794, in _apply_op_helper
    op_def=op_def)
  File "/home/grupo01/anaconda3/lib/python3.7/site-packages/tensorflow_core/python/util/deprecation.py", line 507, in new_func
    return func(*args, **kwargs)
  File "/home/grupo01/anaconda3/lib/python3.7/site-packages/tensorflow_core/python/framework/ops.py", line 3357, in create_op
    attrs, op_def, compute_device)
  File "/home/grupo01/anaconda3/lib/python3.7/site-packages/tensorflow_core/python/framework/ops.py", line 3426, in _create_op_internal
    op_def=op_def)
  File "/home/grupo01/anaconda3/lib/python3.7/site-packages/tensorflow_core/python/framework/ops.py", line 1748, in __init__
    self._traceback = tf_stack.extract_stack()


During handling of the above exception, another exception occurred:

Traceback (most recent call last):
  File "eval.py", line 227, in <module>
    tf.app.run()
  File "/home/grupo01/anaconda3/lib/python3.7/site-packages/tensorflow_core/python/platform/app.py", line 40, in run
    _run(main=main, argv=argv, flags_parser=_parse_flags_tolerate_undef)
  File "/home/grupo01/anaconda3/lib/python3.7/site-packages/absl/app.py", line 299, in run
    _run_main(main, args)
  File "/home/grupo01/anaconda3/lib/python3.7/site-packages/absl/app.py", line 250, in _run_main
    sys.exit(main(argv))
  File "eval.py", line 220, in main
    eval_interval_secs=FLAGS.eval_interval_secs)
  File "/home/grupo01/anaconda3/lib/python3.7/site-packages/tensorflow_core/contrib/training/python/training/evaluation.py", line 448, in evaluate_repeatedly
    session_creator=session_creator, hooks=hooks) as session:
  File "/home/grupo01/anaconda3/lib/python3.7/site-packages/tensorflow_core/python/training/monitored_session.py", line 1014, in __init__
    stop_grace_period_secs=stop_grace_period_secs)
  File "/home/grupo01/anaconda3/lib/python3.7/site-packages/tensorflow_core/python/training/monitored_session.py", line 725, in __init__
    self._sess = _RecoverableSession(self._coordinated_creator)
  File "/home/grupo01/anaconda3/lib/python3.7/site-packages/tensorflow_core/python/training/monitored_session.py", line 1207, in __init__
    _WrappedSession.__init__(self, self._create_session())
  File "/home/grupo01/anaconda3/lib/python3.7/site-packages/tensorflow_core/python/training/monitored_session.py", line 1212, in _create_session
    return self._sess_creator.create_session()
  File "/home/grupo01/anaconda3/lib/python3.7/site-packages/tensorflow_core/python/training/monitored_session.py", line 878, in create_session
    self.tf_sess = self._session_creator.create_session()
  File "/home/grupo01/anaconda3/lib/python3.7/site-packages/tensorflow_core/python/training/monitored_session.py", line 647, in create_session
    init_fn=self._scaffold.init_fn)
  File "/home/grupo01/anaconda3/lib/python3.7/site-packages/tensorflow_core/python/training/session_manager.py", line 290, in prepare_session
    config=config)
  File "/home/grupo01/anaconda3/lib/python3.7/site-packages/tensorflow_core/python/training/session_manager.py", line 204, in _restore_checkpoint
    saver.restore(sess, checkpoint_filename_with_path)
  File "/home/grupo01/anaconda3/lib/python3.7/site-packages/tensorflow_core/python/training/saver.py", line 1326, in restore
    err, "a mismatch between the current graph and the graph")
tensorflow.python.framework.errors_impl.InvalidArgumentError: Restoring from checkpoint failed. This is most likely due to a mismatch between the current graph and the graph from the checkpoint. Please ensure that you have not altered the graph expected based on the checkpoint. Original error:

2 root error(s) found.
  (0) Invalid argument: Assign requires shapes of both tensors to match. lhs shape= [1,1,1024,256] rhs shape= [1,1,1280,256]
	 [[node save/Assign_39 (defined at /home/grupo01/anaconda3/lib/python3.7/site-packages/tensorflow_core/python/framework/ops.py:1748) ]]
  (1) Invalid argument: Assign requires shapes of both tensors to match. lhs shape= [1,1,1024,256] rhs shape= [1,1,1280,256]
	 [[node save/Assign_39 (defined at /home/grupo01/anaconda3/lib/python3.7/site-packages/tensorflow_core/python/framework/ops.py:1748) ]]
	 [[save/RestoreV2/_388]]
0 successful operations.
0 derived errors ignored.

Original stack trace for 'save/Assign_39':
  File "eval.py", line 227, in <module>
    tf.app.run()
  File "/home/grupo01/anaconda3/lib/python3.7/site-packages/tensorflow_core/python/platform/app.py", line 40, in run
    _run(main=main, argv=argv, flags_parser=_parse_flags_tolerate_undef)
  File "/home/grupo01/anaconda3/lib/python3.7/site-packages/absl/app.py", line 299, in run
    _run_main(main, args)
  File "/home/grupo01/anaconda3/lib/python3.7/site-packages/absl/app.py", line 250, in _run_main
    sys.exit(main(argv))
  File "eval.py", line 220, in main
    eval_interval_secs=FLAGS.eval_interval_secs)
  File "/home/grupo01/anaconda3/lib/python3.7/site-packages/tensorflow_core/contrib/training/python/training/evaluation.py", line 448, in evaluate_repeatedly
    session_creator=session_creator, hooks=hooks) as session:
  File "/home/grupo01/anaconda3/lib/python3.7/site-packages/tensorflow_core/python/training/monitored_session.py", line 1014, in __init__
    stop_grace_period_secs=stop_grace_period_secs)
  File "/home/grupo01/anaconda3/lib/python3.7/site-packages/tensorflow_core/python/training/monitored_session.py", line 725, in __init__
    self._sess = _RecoverableSession(self._coordinated_creator)
  File "/home/grupo01/anaconda3/lib/python3.7/site-packages/tensorflow_core/python/training/monitored_session.py", line 1207, in __init__
    _WrappedSession.__init__(self, self._create_session())
  File "/home/grupo01/anaconda3/lib/python3.7/site-packages/tensorflow_core/python/training/monitored_session.py", line 1212, in _create_session
    return self._sess_creator.create_session()
  File "/home/grupo01/anaconda3/lib/python3.7/site-packages/tensorflow_core/python/training/monitored_session.py", line 878, in create_session
    self.tf_sess = self._session_creator.create_session()
  File "/home/grupo01/anaconda3/lib/python3.7/site-packages/tensorflow_core/python/training/monitored_session.py", line 638, in create_session
    self._scaffold.finalize()
  File "/home/grupo01/anaconda3/lib/python3.7/site-packages/tensorflow_core/python/training/monitored_session.py", line 229, in finalize
    self._saver = training_saver._get_saver_or_default()  # pylint: disable=protected-access
  File "/home/grupo01/anaconda3/lib/python3.7/site-packages/tensorflow_core/python/training/saver.py", line 599, in _get_saver_or_default
    saver = Saver(sharded=True, allow_empty=True)
  File "/home/grupo01/anaconda3/lib/python3.7/site-packages/tensorflow_core/python/training/saver.py", line 828, in __init__
    self.build()
  File "/home/grupo01/anaconda3/lib/python3.7/site-packages/tensorflow_core/python/training/saver.py", line 840, in build
    self._build(self._filename, build_save=True, build_restore=True)
  File "/home/grupo01/anaconda3/lib/python3.7/site-packages/tensorflow_core/python/training/saver.py", line 878, in _build
    build_restore=build_restore)
  File "/home/grupo01/anaconda3/lib/python3.7/site-packages/tensorflow_core/python/training/saver.py", line 502, in _build_internal
    restore_sequentially, reshape)
  File "/home/grupo01/anaconda3/lib/python3.7/site-packages/tensorflow_core/python/training/saver.py", line 381, in _AddShardedRestoreOps
    name="restore_shard"))
  File "/home/grupo01/anaconda3/lib/python3.7/site-packages/tensorflow_core/python/training/saver.py", line 350, in _AddRestoreOps
    assign_ops.append(saveable.restore(saveable_tensors, shapes))
  File "/home/grupo01/anaconda3/lib/python3.7/site-packages/tensorflow_core/python/training/saving/saveable_object_util.py", line 73, in restore
    self.op.get_shape().is_fully_defined())
  File "/home/grupo01/anaconda3/lib/python3.7/site-packages/tensorflow_core/python/ops/state_ops.py", line 227, in assign
    validate_shape=validate_shape)
  File "/home/grupo01/anaconda3/lib/python3.7/site-packages/tensorflow_core/python/ops/gen_state_ops.py", line 66, in assign
    use_locking=use_locking, name=name)
  File "/home/grupo01/anaconda3/lib/python3.7/site-packages/tensorflow_core/python/framework/op_def_library.py", line 794, in _apply_op_helper
    op_def=op_def)
  File "/home/grupo01/anaconda3/lib/python3.7/site-packages/tensorflow_core/python/util/deprecation.py", line 507, in new_func
    return func(*args, **kwargs)
  File "/home/grupo01/anaconda3/lib/python3.7/site-packages/tensorflow_core/python/framework/ops.py", line 3357, in create_op
    attrs, op_def, compute_device)
  File "/home/grupo01/anaconda3/lib/python3.7/site-packages/tensorflow_core/python/framework/ops.py", line 3426, in _create_op_internal
    op_def=op_def)
  File "/home/grupo01/anaconda3/lib/python3.7/site-packages/tensorflow_core/python/framework/ops.py", line 1748, in __init__
    self._traceback = tf_stack.extract_stack()

